<?xml version="1.0"?>
<robot name="champi_arm" xmlns:xacro="http://www.ros.org/wiki/xacro">

  <!-- Link 1 -->
  <link name="link1">
    <visual>
      <geometry>
        <cylinder length="1" radius="0.05"/>
      </geometry>
    </visual>
  </link>

  <!-- Link 2 -->
  <link name="link2">
    <visual>
      <geometry>
        <cylinder length="1" radius="0.05"/>
      </geometry>
    </visual>
  </link>

  <!-- Link 3 -->
  <link name="link3">
    <visual>
      <geometry>
        <cylinder length="1" radius="0.05"/>
      </geometry>
    </visual>
  </link>

  <!-- Joint1 -->
  <joint name="joint1" type="revolute">
    <parent link="link1"/>
    <child link="link2"/>
    <origin xyz="0 0 1" rpy="0 0 0"/>
    <axis xyz="0 1 0"/>
    <limit lower="-1.57" upper="1.57" effort="100.0" velocity="0.5"/>
  </joint>

  <!-- Joint2 -->
  <joint name="joint2" type="revolute">
    <parent link="link2"/>
    <child link="link3"/>
    <origin xyz="0 0 1" rpy="0 0 0"/>
    <axis xyz="0 1 0"/>
    <limit lower="-1.57" upper="1.57" effort="100.0" velocity="0.5"/>
  </joint>

  <ros2_control name="dynamixel1" type="system">
      <hardware>
        <plugin>dynamixel_hardware/DynamixelHardware</plugin>
        <param name="usb_port">/dev/ttyUSB0</param>
        <param name="baud_rate">57600</param>
        <!-- <param name="use_dummy">true</param> -->
      </hardware>
      <joint name="joint1">
        <param name="id">13</param>
        <command_interface name="position"/>
        <state_interface name="position"/>
        <state_interface name="effort"/>
      </joint>
      <joint name="joint2">
        <param name="id">11</param>
        <command_interface name="position"/>
        <state_interface name="position"/>
        <state_interface name="effort"/>
      </joint>


    </ros2_control>

</robot>